Workbook

Sheet Human Development Index 2022
A1: Region | B1: Human Development Index 2022
A2: Somalia | B2: 0.38
A3: South Sudan | B3: 0.381
A4: Central African Republic | B4: 0.387
A5: Niger | B5: 0.394
A6: Chad | B6: 0.394
A7: Mali | B7: 0.41
A8: Burundi | B8: 0.42
A9: Yemen | B9: 0.424
A10: Burkina Faso | B10: 0.438
A11: Sierra Leone | B11: 0.458
A12: Mozambique | B12: 0.461
A13: Afghanistan | B13: 0.462
... A194: Switzerland | B194: 0.967

Sheet 202503421 Tourism Ireland - Dis
A1: Household disposable income
A2: US dollars/capita, 2023
A3: Category | B3: Gross disposable income per capita of households and NPISH
A4: United States | B4: 63084.019
A5: Luxembourg | B5: 50501.349
A6: Switzerland | B6: 47123.85
A7: Germany | B7: 42417.404
A8: Australia | B8: 41199.647
A9: Austria | B9: 40933.733
A10: Belgium | B10: 37365.363
A11: Netherlands | B11: 36367.868
A12: United Kingdom | B12: 36196.55
A13: Canada | B13: 35560.624
A14: France | B14: 35000.876
A15: Italy | B15: 34673.924
... A20: Denmark | B20: 30101.188
A23: https://www.oecd.org/en/data/indicators/household-disposable-income.html?oecdcontrol-3fafbcc227-var1=USA%7CGBR%7CDEU%7CFRA%7CESP%7CITA%7CCAN%7CAUS%7CNZL%7CBEL%7CLUX%7CNLD%7CDNK%7CFIN%7CIRL%7CNOR%7CSWE%7CCHE%7CAUT

Sheet Country Decoder - Final 2503205
X1: Outputs | Z1: 350000000 | AG1: Change Y1 to allocate budget across markets
A2: Audience Ratio to Departure | B2: Audience(m) | C2: SV -AD | D2: SV - Flights to AD | E2: SV - AD 23 | F2: SV - Flights to AD 23 | G2: Population | H2: Tourist Departures | I2: Trips(000s) | J2: Spend(m-euro) | L2: Country | M2: Spends Per Trip | N2: Tourist Departures / Population | O2: Search Volume - 'Flight to Abu Dhabi' | P2: =GDP!D1 -> GDP - Growth | Q2: =DPI!B1 -> Disposable Personal Income (USD) | R2: ='Cost of Media'!B1 -> Media Cost | S2: Global Explorers (Audience M) | T2: Budget Split | U2: Market Tiering | V2: Audience Ratio vs. Total Population | X2: Weighted Score | Y2: % Split | Z2: Budget Split | AG2: if you want to change the allocation of a market, simply change it's Market Tiering in U column and paste the new values from W36
A3: =B3/G3 -> 0.40366969 | B3: 4581651 | C3: 18791890 | D3: 69430 | E3: 9975490 | F3: 85740 | G3: 11350000 | H3: 18906000 | I3: 2000 | J3: 230 | L3: UAE | M3: 5.8321579 | N3: =H3/G3 -> 1.6657269 | O3: =C3+D3+E3+F3 -> 28922550 | P3: =VLOOKUP(L3,GDP!$A$2:$D$27,4,FALSE) -> 0.021447497 | Q3: =VLOOKUP(L3,DPI!$A$1:$B$27,2,FALSE) -> 36020 | R3: 7.8 | S3: =B3/1000000 -> 4.581651 | T3: 10 | U3: 2 | V3: =A3 -> 0.40366969 | X3: =SUMPRODUCT($M$32:$V$32,M37:V37) -> 106.74562 | Y3: =X3/SUM($X$3:$X$28) -> 0.034670708 | Z3: =Y3*$Z$1 -> 12134748 | AG3: (green markets are Tier 1, Yellows are Tier 2)
A4: =B4/G4 -> 0.035599178 | B4: 12367235 | C4: 3036780 | D4: 70340 | E4: 2947460 | F4: 48810 | G4: 347402264 | H4: 1.7093009e+08 | I4: 704.9 | J4: 21540 | L4: USA | M4: 10 | N4: =H4/G4 -> 0.49202355 | O4: =C4+D4+E4+F4 -> 6103390 | P4: =VLOOKUP(L4,GDP!$A$2:$D$27,4,FALSE) -> 0.045333059 | Q4: =VLOOKUP(L4,DPI!$A$1:$B$27,2,FALSE) -> 60944 | R4: 12 | S4: =B4/1000000 -> 12.367235 | T4: 2.5 | U4: 10 | V4: =A4 -> 0.035599178 | X4: =SUMPRODUCT($M$32:$V$32,M38:V38) -> 223.84196 | Y4: =X4/SUM($X$3:$X$28) -> 0.072703305 | Z4: =Y4*$Z$1 -> 25446157
A5: =B5/G5 -> 0.086109479 | B5: 5991450 | C5: 2248410 | D5: 169080 | E5: 1782130 | F5: 136400 | G5: 69579448 | H5: 93086000 | I5: 1245.1 | J5: 7400 | L5: UK | M5: 6.0043325 | N5: =H5/G5 -> 1.3378376 | O5: =C5+D5+E5+F5 -> 4336020 | P5: =VLOOKUP(L5,GDP!$A$2:$D$27,4,FALSE) -> 0.053512623 | Q5: =VLOOKUP(L5,DPI!$A$1:$B$27,2,FALSE) -> 36077 | R5: 9.5 | S5: =B5/1000000 -> 5.99145 | T5: 2.6 | U5: 10 | V5: =A5 -> 0.086109479 | X5: =SUMPRODUCT($M$32:$V$32,M39:V39) -> 220.45948 | Y5: =X5/SUM($X$3:$X$28) -> 0.071604685 | Z5: =Y5*$Z$1 -> 25061640
A6: =B6/G6 -> 0.062525275 | B6: 5227113 | C6: 1384090 | D6: 5530 | E6: 1351080 | F6: 3820 | G6: 83600000 | H6: 99533000 | I6: 504.2 | J6: 11200 | L6: Germany | M6: 4.4833256 | N6: =H6/G6 -> 1.1905861 | O6: =C6+D6+E6+F6 -> 2744520 | P6: =VLOOKUP(L6,GDP!$A$2:$D$27,4,FALSE) -> 0.01846286 | Q6: =VLOOKUP(L6,DPI!$A$1:$B$27,2,FALSE) -> 42417 | R6: 7.5 | S6: =B6/1000000 -> 5.227113 | T6: 1.6 | U6: 10 | V6: =A6 -> 0.062525275 | X6: =SUMPRODUCT($M$32:$V$32,M40:V40) -> 211.90058 | Y6: =X6/SUM($X$3:$X$28) -> 0.068824776 | Z6: =Y6*$Z$1 -> 24088672
A7: =B7/G7 -> 0.065790013 | B7: 4385431 | C7: 1319680 | D7: 4240 | E7: 1175450 | F7: 2830 | G7: 66658005 | H7: 49276000 | I7: 433.9 | J7: 3600 | L7: France | M7: 5.8127874 | N7: =H7/G7 -> 0.73923605 | O7: =C7+D7+E7+F7 -> 2502200 | P7: =VLOOKUP(L7,GDP!$A$2:$D$27,4,FALSE) -> 0.015496521 | Q7: =VLOOKUP(L7,DPI!$A$1:$B$27,2,FALSE) -> 35001 | R7: 7 | S7: =B7/1000000 -> 4.385431 | T7: 1.6 | U7: 10 | V7: =A7 -> 0.065790013 | X7: =SUMPRODUCT($M$32:$V$32,M41:V41) -> 210.75121 | Y7: =X7/SUM($X$3:$X$28) -> 0.068451464 | Z7: =Y7*$Z$1 -> 23958012
A8: =B8/G8 -> 0.051211681 | B8: 5954662 | C8: 172870 | D8: 14650 | E8: 149110 | F8: 8400 | G8: 116275465 | H8: 43066000 | I8: 170 | J8: 490 | L8: Egypt | M8: 1.0681261 | N8: =H8/G8 -> 0.37037908 | O8: =C8+D8+E8+F8 -> 345030 | P8: =VLOOKUP(L8,GDP!$A$2:$D$27,4,FALSE) -> -0.093359853 | Q8: =VLOOKUP(L8,DPI!$A$1:$B$27,2,FALSE) -> 2072 | R8: 3.2 | S8: =B8/1000000 -> 5.954662 | T8: 1 | U8: 1 | V8: =A8 -> 0.051211681 | X8: =SUMPRODUCT($M$32:$V$32,M42:V42) -> 59.364733 | Y8: =X8/SUM($X$3:$X$28) -> 0.019281516 | Z8: =Y8*$Z$1 -> 6748530.5
A9: =B9/G9 -> 0.074306582 | B9: 1513675 | C9: 71900 | D9: 290 | E9: 47810 | F9: 190 | G9: 20370672 | H9: 10707000 | I9: 74 | J9: 180 | L9: Khazakstan | M9: 2.0806578 | N9: =H9/G9 -> 0.52560858 | O9: =C9+D9+E9+F9 -> 120190 | P9: =VLOOKUP(L9,GDP!$A$2:$D$27,4,FALSE) -> 0.05522278 | Q9: =VLOOKUP(L9,DPI!$A$1:$B$27,2,FALSE) -> 9660 | R9: 2.8 | S9: =B9/1000000 -> 1.513675 | T9: 3 | U9: 1 | V9: =A9 -> 0.074306582 | X9: =SUMPRODUCT($M$32:$V$32,M43:V43) -> 66.696784 | Y9: =X9/SUM($X$3:$X$28) -> 0.021662948 | Z9: =Y9*$Z$1 -> 7582031.7
A10: =B10/G10 -> 0.73347706 | B10: 1165253 | C10: 94410 | D10: 12270 | E10: 87090 | F10: 12260 | G10: 1588670 | H10: 1950000 | I10: 52.4 | J10: 260 | L10: Bahrain | M10: 4.2309976 | N10: =H10/G10 -> 1.2274418 | O10: =C10+D10+E10+F10 -> 206030 | P10: =VLOOKUP(L10,GDP!$A$2:$D$27,4,FALSE) -> 0.018873954 | Q10: =VLOOKUP(L10,DPI!$A$1:$B$27,2,FALSE) -> 25947 | R10: 4.4 | S10: =B10/1000000 -> 1.165253 | T10: 1 | U10: 0.05 | V10: =A10 -> 0.73347706 | X10: =SUMPRODUCT($M$32:$V$32,M44:V44) -> 54.617531 | Y10: =X10/SUM($X$3:$X$28) -> 0.017739637 | Z10: =Y10*$Z$1 -> 6208872.8 | AE10: <-- | AF10: aim for 4m
A11: =B11/G11 -> 0.94645448 | B11: 2744718 | C11: 139980 | D11: 16220 | E11: 98020 | F11: 14480 | G11: 2900000 | H11: 3550000 | I11: 1000 | J11: 1350 | L11: Qatar | M11: 4.1472032 | N11: =H11/G11 -> 1.2241379 | O11: =C11+D11+E11+F11 -> 268700 | P11: =VLOOKUP(L11,GDP!$A$2:$D$27,4,FALSE) -> 0.0059787223 | Q11: =VLOOKUP(L11,DPI!$A$1:$B$27,2,FALSE) -> 17459 | R11: 5.5 | S11: =B11/1000000 -> 2.744718 | T11: 4 | U11: 0.05 | V11: =A11 -> 0.94645448 | X11: =SUMPRODUCT($M$32:$V$32,M45:V45) -> 65.091672 | Y11: =X11/SUM($X$3:$X$28) -> 0.021141611 | Z11: =Y11*$Z$1 -> 7399563.9
A12: =B12/G12 -> 0.037670506 | B12: 1563326 | C12: 604940 | D12: 9120 | E12: 575590 | F12: 6950 | G12: 41500000 | H12: 37845898 | I12: 59 | J12: 2500 | L12: Canada | M12: 4.0831246 | N12: =H12/G12 -> 0.91194936 | O12: =C12+D12+E12+F12 -> 1196600 | P12: =VLOOKUP(L12,GDP!$A$2:$D$27,4,FALSE) -> -0.0071396698 | Q12: =VLOOKUP(L12,DPI!$A$1:$B$27,2,FALSE) -> 35561 | R12: 9 | S12: =B12/1000000 -> 1.563326 | T12: 1.2 | U12: 1 | V12: =A12 -> 0.037670506 | X12: =SUMPRODUCT($M$32:$V$32,M46:V46) -> 80.443355 | Y12: =X12/SUM($X$3:$X$28) -> 0.026127799 | Z12: =Y12*$Z$1 -> 9144729.7
A13: =B13/G13 -> 0.077463605 | B13: 1504678 | C13: 286520 | D13: 760 | E13: 244350 | F13: 570 | G13: 19424322 | H13: 23066000 | I13: 35.1 | J13: 930 | L13: Romania | M13: 2.2604101 | N13: =H13/G13 -> 1.1874803 | O13: =C13+D13+E13+F13 -> 532200 | P13: =VLOOKUP(L13,GDP!$A$2:$D$27,4,FALSE) -> 0.012562814 | Q13: =VLOOKUP(L13,DPI!$A$1:$B$27,2,FALSE) -> 7532 | R13: 3.5 | S13: =B13/1000000 -> 1.504678 | T13: 3 | U13: 1 | V13: =A13 -> 0.077463605 | X13: =SUMPRODUCT($M$32:$V$32,M47:V47) -> 67.726059 | Y13: =X13/SUM($X$3:$X$28) -> 0.021997253 | Z13: =Y13*$Z$1 -> 7699038.7
A14: =B14/G14 -> 0.094624099 | B14: 452370 | C14: 139390 | D14: 1260 | E14: 98490 | F14: 1000 | G14: 4780706 | H14: 6633000 | I14: 1565.8 | J14: 470 | L14: Oman | M14: 1.6150578 | N14: =H14/G14 -> 1.387452 | O14: =C14+D14+E14+F14 -> 240140 | P14: =VLOOKUP(L14,GDP!$A$2:$D$27,4,FALSE) -> -0.02423721 | Q14: =VLOOKUP(L14,DPI!$A$1:$B$27,2,FALSE) -> 16800 | R14: 3.8 | S14: =B14/1000000 -> 0.45237 | T14: 3.5 | U14: 0.05 | V14: =A14 -> 0.094624099 | X14: =SUMPRODUCT($M$32:$V$32,M48:V48) -> 57.374399 | Y14: =X14/SUM($X$3:$X$28) -> 0.01863506 | Z14: =Y14*$Z$1 -> 6522271.1
A15: =B15/G15 -> 0.036562023 | B15: 1733772 | C15: 641800 | D15: 2170 | E15: 609940 | F15: 1750 | G15: 47420024 | H15: 22816000 | I15: 52.8 | J15: 5700 | L15: Spain | M15: 3.6563048 | N15: =H15/G15 -> 0.48114695 | O15: =C15+D15+E15+F15 -> 1255660 | P15: =VLOOKUP(L15,GDP!$A$2:$D$27,4,FALSE) -> 0.044715447 | Q15: =VLOOKUP(L15,DPI!$A$1:$B$27,2,FALSE) -> 31193 | R15: 6.5 | S15: =B15/1000000 -> 1.733772 | T15: 1.2 | U15: 1 | V15: =A15 -> 0.036562023 | X15: =SUMPRODUCT($M$32:$V$32,M49:V49) -> 73.745254 | Y15: =X15/SUM($X$3:$X$28) -> 0.023952273 | Z15: =Y15*$Z$1 -> 8383295.5
A16: =B16/G16 -> 0.13368511 | B16: 2369212 | C16: 442290 | D16: 4160 | E16: 431370 | F16: 3130 | G16: 17722333 | H16: 22045000 | I16: 61.4 | J16: 2670 | L16: Netherlands | M16: 5.6280836 | N16: =H16/G16 -> 1.2439107 | O16: =C16+D16+E16+F16 -> 880950 | P16: =VLOOKUP(L16,GDP!$A$2:$D$27,4,FALSE) -> 0.036674817 | Q16: =VLOOKUP(L16,DPI!$A$1:$B$27,2,FALSE) -> 40722 | R16: 7.2 | S16: =B16/1000000 -> 2.369212 | T16: 1.2 | U16: 1 | V16: =A16 -> 0.13368511 | X16: =SUMPRODUCT($M$32:$V$32,M50:V50) -> 78.538496 | Y16: =X16/SUM($X$3:$X$28) -> 0.025509106 | Z16: =Y16*$Z$1 -> 8928187
A17: =B17/G17 -> 0.0058892883 | B17: 718260 | C17: 161240 | D17: 72490 | E17: 520 | F17: 360 | G17: 121960408 | H17: 20081000 | I17: 27 | J17: 1140 | L17: Japan | M17: 6.3468851 | N17: =H17/G17 -> 0.16465179 | O17: =C17+D17+E17+F17 -> 234610 | P17: =VLOOKUP(L17,GDP!$A$2:$D$27,4,FALSE) -> 0.039741679 | Q17: =VLOOKUP(L17,DPI!$A$1:$B$27,2,FALSE) -> 28040 | R17: 8.5 | S17: =B17/1000000 -> 0.71826 | T17: 1.3 | U17: 1 | V17: =A17 -> 0.0058892883 | X17: =SUMPRODUCT($M$32:$V$32,M51:V51) -> 80.714099 | Y17: =X17/SUM($X$3:$X$28) -> 0.026215736 | Z17: =Y17*$Z$1 -> 9175507.6
A18: =B18/G18 -> 0.036384716 | B18: 1349855 | C18: 62390 | D18: 370 | E18: 54330 | F18: 290 | G18: 37099506 | H18: 8437000 | I18: 104.6 | J18: 110 | L18: Uzbekistan | M18: 3.9248221 | N18: =H18/G18 -> 0.22741543 | O18: =C18+D18+E18+F18 -> 117380 | P18: =VLOOKUP(L18,GDP!$A$2:$D$27,4,FALSE) -> 0.15241558 | Q18: =VLOOKUP(L18,DPI!$A$1:$B$27,2,FALSE) -> 1706 | R18: 2.2 | S18: =B18/1000000 -> 1.349855 | T18: 2.5 | U18: 1 | V18: =A18 -> 0.036384716 | X18: =SUMPRODUCT($M$32:$V$32,M52:V52) -> 65.584656 | Y18: =X18/SUM($X$3:$X$28) -> 0.021301731 | Z18: =Y18*$Z$1 -> 7455605.9
A19: =B19/G19 -> 0.11301397 | B19: 4477244 | C19: 663510 | D19: 1550 | E19: 585130 | F19: 1550 | G19: 39616730 | H19: 50600000 | I19: 40.7 | J19: 1570 | L19: Poland | M19: 2.6190282 | N19: =H19/G19 -> 1.2772382 | O19: =C19+D19+E19+F19 -> 1251740 | P19: =VLOOKUP(L19,GDP!$A$2:$D$27,4,FALSE) -> 0.078193833 | Q19: =VLOOKUP(L19,DPI!$A$1:$B$27,2,FALSE) -> 10080 | R19: 4.5 | S19: =B19/1000000 -> 4.477244 | T19: 1 | U19: 1 | V19: =A19 -> 0.11301397 | X19: =SUMPRODUCT($M$32:$V$32,M53:V53) -> 64.776156 | Y19: =X19/SUM($X$3:$X$28) -> 0.021039132 | Z19: =Y19*$Z$1 -> 7363696.3 | AG19: =200/350 -> 0.57142857
A20: =B20/G20 -> 0.0043850772 | B20: 227147 | C20: 59540 | D20: 330 | E20: 44400 | F20: 330 | G20: 51800000 | H20: 28714000 | I20: 37.7 | J20: 2280 | L20: South Korea | M20: 4.0416603 | N20: =H20/G20 -> 0.55432432 | O20: =C20+D20+E20+F20 -> 104600 | P20: =VLOOKUP(L20,GDP!$A$2:$D$27,4,FALSE) -> -0.042268593 | Q20: =VLOOKUP(L20,DPI!$A$1:$B$27,2,FALSE) -> 36230 | R20: 8 | S20: =B20/1000000 -> 0.227147 | T20: 1.1 | U20: 1 | V20: =A20 -> 0.0043850772 | X20: =SUMPRODUCT($M$32:$V$32,M54:V54) -> 77.624376 | Y20: =X20/SUM($X$3:$X$28) -> 0.025212202 | Z20: =Y20*$Z$1 -> 8824270.7
A21: =B21/G21 -> 0.12419864 | B21: 344900 | C21: 136500 | D21: 570 | E21: 69270 | F21: 570 | G21: 2777003 | H21: 1868000 | I21: 12 | J21: 30 | L21: Armenia | M21: 2.0528138 | N21: =H21/G21 -> 0.67266762 | O21: =C21+D21+E21+F21 -> 206910 | P21: =VLOOKUP(L21,GDP!$A$2:$D$27,4,FALSE) -> 0.028394627 | Q21: =VLOOKUP(L21,DPI!$A$1:$B$27,2,FALSE) -> 2555 | R21: 2.8 | S21: =B21/1000000 -> 0.3449 | T21: 2 | U21: 1 | V21: =A21 -> 0.12419864 | X21: =SUMPRODUCT($M$32:$V$32,M55:V55) -> 62.828597 | Y21: =X21/SUM($X$3:$X$28) -> 0.02040657 | Z21: =Y21*$Z$1 -> 7142299.5
A22: =B22/G22 -> 0.097492624 | B22: 1152904 | C22: 285990 | D22: 990 | E22: 221500 | F22: 740 | G22: 11825551 | H22: 14191000 | I22: 36.6 | J22: 2700 | L22: Belgium | M22: 6.8996981 | N22: =H22/G22 -> 1.2000286 | O22: =C22+D22+E22+F22 -> 509220 | P22: =VLOOKUP(L22,GDP!$A$2:$D$27,4,FALSE) -> 0.037650602 | Q22: =VLOOKUP(L22,DPI!$A$1:$B$27,2,FALSE) -> 37365 | R22: 6.5 | S22: =B22/1000000 -> 1.152904 | T22: 1.1 | U22: 1 | V22: =A22 -> 0.097492624 | X22: =SUMPRODUCT($M$32:$V$32,M56:V56) -> 76.550766 | Y22: =X22/SUM($X$3:$X$28) -> 0.024863496 | Z22: =Y22*$Z$1 -> 8702223.6
A23: =B23/G23 -> 0.021331154 | B23: 1257134 | C23: 1076490 | D23: 3370 | E23: 1109260 | F23: 3220 | G23: 58934177 | H23: 62207000 | I23: 247 | J23: 5600 | L23: Italy | M23: 4.996738 | N23: =H23/G23 -> 1.0555335 | O23: =C23+D23+E23+F23 -> 2192340 | P23: =VLOOKUP(L23,GDP!$A$2:$D$27,4,FALSE) -> 0.021079258 | Q23: =VLOOKUP(L23,DPI!$A$1:$B$27,2,FALSE) -> 34703 | R23: 7.5 | S23: =B23/1000000 -> 1.257134 | T23: 1.3 | U23: 10 | V23: =A23 -> 0.021331154 | X23: =SUMPRODUCT($M$32:$V$32,M57:V57) -> 210.60139 | Y23: =X23/SUM($X$3:$X$28) -> 0.068402801 | Z23: =Y23*$Z$1 -> 23940980
A24: =B24/G24 -> 0.036996134 | B24: 52696625 | C24: 32530 | D24: 160 | E24: 21260 | F24: 160 | G24: 1424381924 | H24: 154632000 | I24: 177 | J24: 19650 | L24: China | M24: 1 | N24: =H24/G24 -> 0.10856077 | O24: =C24+D24+E24+F24 -> 54110 | P24: =VLOOKUP(L24,GDP!$A$2:$D$27,4,FALSE) -> 0.025762748 | Q24: =VLOOKUP(L24,DPI!$A$1:$B$27,2,FALSE) -> 5738 | R24: 11.5 | S24: =B24/1000000 -> 52.696625 | T24: 1.7 | U24: 10 | V24: =A24 -> 0.036996134 | X24: =SUMPRODUCT($M$32:$V$32,M58:V58) -> 211.99148 | Y24: =X24/SUM($X$3:$X$28) -> 0.068854299 | Z24: =Y24*$Z$1 -> 24099005
A25: =B25/G25 -> 0.23580106 | B25: 8958075 | C25: 390390 | D25: 17520 | E25: 243830 | F25: 13820 | G25: 37989969 | H25: 27196000 | I25: 1452.6 | J25: 600 | L25: Saudi Arabia | M25: 2.0912532 | N25: =H25/G25 -> 0.71587318 | O25: =C25+D25+E25+F25 -> 665560 | P25: =VLOOKUP(L25,GDP!$A$2:$D$27,4,FALSE) -> -0.0014824602 | Q25: =VLOOKUP(L25,DPI!$A$1:$B$27,2,FALSE) -> 10224 | R25: 6.5 | S25: =B25/1000000 -> 8.958075 | T25: 1.3 | U25: 10 | V25: =A25 -> 0.23580106 | X25: =SUMPRODUCT($M$32:$V$32,M59:V59) -> 202.2057 | Y25: =X25/SUM($X$3:$X$28) -> 0.065675902 | Z25: =Y25*$Z$1 -> 22986566
A26: =B26/G26 -> 0.038245221 | B26: 5504874 | C26: 1447698 | D26: 27896 | E26: 994422 | F26: 18822 | G26: 143936258 | H26: 45330000 | I26: 905.5 | J26: 500 | L26: Russia | M26: 1.9591423 | N26: =H26/G26 -> 0.31493107 | O26: =C26+D26+E26+F26 -> 2488838 | P26: =VLOOKUP(L26,GDP!$A$2:$D$27,4,FALSE) -> -0.039333642 | Q26: =VLOOKUP(L26,DPI!$A$1:$B$27,2,FALSE) -> 9053 | R26: 3.8 | S26: =B26/1000000 -> 5.504874 | T26: 1.1 | U26: 10 | V26: =A26 -> 0.038245221 | X26: =SUMPRODUCT($M$32:$V$32,M60:V60) -> 193.9838 | Y26: =X26/SUM($X$3:$X$28) -> 0.063005449 | Z26: =Y26*$Z$1 -> 22051907
A27: =B27/G27 -> 0.64767527 | B27: 2841422 | C27: 156750 | D27: 14530 | E27: 136790 | F27: 11620 | G27: 4387109 | H27: 2950000 | I27: 84 | J27: 50 | L27: Kuwait | M27: 2.6880376 | N27: =H27/G27 -> 0.6724246 | O27: =C27+D27+E27+F27 -> 319690 | P27: =VLOOKUP(L27,GDP!$A$2:$D$27,4,FALSE) -> -0.034477322 | Q27: =VLOOKUP(L27,DPI!$A$1:$B$27,2,FALSE) -> 26600 | R27: 5.2 | S27: =B27/1000000 -> 2.841422 | T27: 1.1 | U27: 0.05 | V27: =A27 -> 0.64767527 | X27: =SUMPRODUCT($M$32:$V$32,M61:V61) -> 55.155708 | Y27: =X27/SUM($X$3:$X$28) -> 0.017914435 | Z27: =Y27*$Z$1 -> 6270052.3
A28: =B28/G28 -> 0.081823974 | B28: 119021703 | C28: 3792180 | D28: 206010 | E28: 2800880 | F28: 111580 | G28: 1454606724 | H28: 26915000 | I28: 2200.3 | J28: 1340 | L28: India | M28: 3.3116351 | N28: =H28/G28 -> 0.018503283 | O28: =C28+D28+E28+F28 -> 6910650 | P28: =VLOOKUP(L28,GDP!$A$2:$D$27,4,FALSE) -> 0.071117933 | Q28: =VLOOKUP(L28,DPI!$A$1:$B$27,2,FALSE) -> 2531 | R28: 3.5 | S28: =B28/1000000 -> 119.0217 | T28: 2.1 | U28: 10 | V28: =A28 -> 0.081823974 | X28: =SUMPRODUCT($M$32:$V$32,M62:V62) -> 199.52774 | Y28: =X28/SUM($X$3:$X$28) -> 0.064806106 | Z28: =Y28*$Z$1 -> 22682137
L29: Avg | M29: =AVERAGE(M3:M28) -> 3.9551647 | N29: =AVERAGE(N3:N28) -> 0.80642574 | O29: =AVERAGE(O3:O28) -> 2488839.5 | P29: =AVERAGE(P3:P28) -> 0.020782254 | Q29: =AVERAGE(Q3:Q28) -> 23162.692 | R29: =AVERAGE(R3:R28) -> 6.1615385 | S29: =AVERAGE(S3:S28) -> 9.6194111 | T29: =AVERAGE(T3:T28) -> 2.1153846 | ... V29: =AVERAGE(V3:V28) -> 0.16470715 | Z29: =+SUM(Z3:Z28)=Z1 -> TRUE
L30: St Dv | M30: =STDEV(M3:M28) -> 2.1005276 | N30: =STDEV(N3:N28) -> 0.46157889 | O30: =STDEV(O3:O28) -> 5695386.2 | P30: =STDEV(P3:P28) -> 0.046847441 | Q30: =STDEV(Q3:Q28) -> 16052.908 | R30: =STDEV(R3:R28) -> 2.673137 | S30: =STDEV(S3:S28) -> 24.493177 | T30: =STDEV(T3:T28) -> 1.8200423 | ... V30: =STDEV(V3:V28) -> 0.24299524
U31: Edited for Pan Arab TV impact
L32: Model Weight | M32: 5 | N32: 0.5 | O32: 2 | P32: 1 | Q32: 5 | R32: 20 | S32: 2 | T32: 15 | U32: 200 | V32: 0.01
K35: Index Table
K36: Tier | L36: Country | M36: =_xlfn.CONCAT(M2," Index") -> Spends Per Trip Index | N36: =_xlfn.CONCAT(N2," Index") -> Tourist Departures / Population Index | O36: =_xlfn.CONCAT(O2," Index") -> Search Volume - 'Flight to Abu Dhabi' Index | P36: =_xlfn.CONCAT(P2," Index") -> GDP - Growth Index | Q36: =_xlfn.CONCAT(Q2," Index") -> Disposable Personal Income (USD) Index | R36: =_xlfn.CONCAT(R2," Index") -> Media Cost Index | S36: =_xlfn.CONCAT(S2," Index") -> Global Explorers (Audience M) Index | T36: =_xlfn.CONCAT(T2," Index") -> Budget Split Index | ... V36: =_xlfn.CONCAT(V2," Index") -> Audience Ratio vs. Total Population Index
K37: Tier 1 | L37: UAE | M37: =_xlfn.NORM.DIST(M3,M$29,M$30,TRUE) -> 0.81422715 | N37: =_xlfn.NORM.DIST(N3,N$29,N$30,TRUE) -> 0.9686742 | O37: =_xlfn.NORM.DIST(O3,O$29,O$30,TRUE) -> 0.99999827 | P37: =_xlfn.NORM.DIST(P3,P$29,P$30,TRUE) -> 0.50566487 | Q37: =_xlfn.NORM.DIST(Q3,Q$29,Q$30,TRUE) -> 0.78841486 | R37: =_xlfn.NORM.DIST(R3,R$29,R$30,TRUE) -> 0.73004062 | S37: =_xlfn.NORM.DIST(S3,S$29,S$30,TRUE) -> 0.41852039 | T37: =_xlfn.NORM.DIST(T3,T$29,T$30,TRUE) -> 0.99999262 | ... V37: =_xlfn.NORM.DIST(V3,V$29,V$30,TRUE) -> 0.83729573 | AH37: 7.8
K38: Tier 1 | L38: USA | M38: =_xlfn.NORM.DIST(M4,M$29,M$30,TRUE) -> 0.99799751 | N38: =_xlfn.NORM.DIST(N4,N$29,N$30,TRUE) -> 0.24788984 | O38: =_xlfn.NORM.DIST(O4,O$29,O$30,TRUE) -> 0.73717013 | P38: =_xlfn.NORM.DIST(P4,P$29,P$30,TRUE) -> 0.69988112 | Q38: =_xlfn.NORM.DIST(Q4,Q$29,Q$30,TRUE) -> 0.99070243 | R38: =_xlfn.NORM.DIST(R4,R$29,R$30,TRUE) -> 0.98552341 | S38: =_xlfn.NORM.DIST(S4,S$29,S$30,TRUE) -> 0.54466256 | T38: =_xlfn.NORM.DIST(T4,T$29,T$30,TRUE) -> 0.58368208 | ... V38: =_xlfn.NORM.DIST(V4,V$29,V$30,TRUE) -> 0.2975989 | AH38: 12
K39: Tier 1 | L39: UK | M39: =_xlfn.NORM.DIST(M5,M$29,M$30,TRUE) -> 0.83535601 | N39: =_xlfn.NORM.DIST(N5,N$29,N$30,TRUE) -> 0.87519382 | O39: =_xlfn.NORM.DIST(O5,O$29,O$30,TRUE) -> 0.62715562 | P39: =_xlfn.NORM.DIST(P5,P$29,P$30,TRUE) -> 0.75761731 | Q39: =_xlfn.NORM.DIST(Q5,Q$29,Q$30,TRUE) -> 0.78944125 | R39: =_xlfn.NORM.DIST(R5,R$29,R$30,TRUE) -> 0.89414785 | S39: =_xlfn.NORM.DIST(S5,S$29,S$30,TRUE) -> 0.44112352 | T39: =_xlfn.NORM.DIST(T5,T$29,T$30,TRUE) -> 0.60498282 | ... V39: =_xlfn.NORM.DIST(V5,V$29,V$30,TRUE) -> 0.37317589 | AH39: 9.5
K40: Tier 1 | L40: Germany | M40: =_xlfn.NORM.DIST(M6,M$29,M$30,TRUE) -> 0.59926381 | N40: =_xlfn.NORM.DIST(N6,N$29,N$30,TRUE) -> 0.79737301 | O40: =_xlfn.NORM.DIST(O6,O$29,O$30,TRUE) -> 0.51790353 | P40: =_xlfn.NORM.DIST(P6,P$29,P$30,TRUE) -> 0.48025662 | Q40: =_xlfn.NORM.DIST(Q6,Q$29,Q$30,TRUE) -> 0.88481923 | R40: =_xlfn.NORM.DIST(R6,R$29,R$30,TRUE) -> 0.69171174 | S40: =_xlfn.NORM.DIST(S6,S$29,S$30,TRUE) -> 0.42884031 | T40: =_xlfn.NORM.DIST(T6,T$29,T$30,TRUE) -> 0.38852258 | ... V40: =_xlfn.NORM.DIST(V6,V$29,V$30,TRUE) -> 0.33705654 | AH40: 7.5
K41: Tier 1 | L41: France | M41: =_xlfn.NORM.DIST(M7,M$29,M$30,TRUE) -> 0.81174906 | N41: =_xlfn.NORM.DIST(N7,N$29,N$30,TRUE) -> 0.44213243 | O41: =_xlfn.NORM.DIST(O7,O$29,O$30,TRUE) -> 0.50093585 | P41: =_xlfn.NORM.DIST(P7,P$29,P$30,TRUE) -> 0.45508321 | Q41: =_xlfn.NORM.DIST(Q7,Q$29,Q$30,TRUE) -> 0.76957735 | R41: =_xlfn.NORM.DIST(R7,R$29,R$30,TRUE) -> 0.62311112 | S41: =_xlfn.NORM.DIST(S7,S$29,S$30,TRUE) -> 0.41539388 | T41: =_xlfn.NORM.DIST(T7,T$29,T$30,TRUE) -> 0.38852258 | ... V41: =_xlfn.NORM.DIST(V7,V$29,V$30,TRUE) -> 0.34197668 | AH41: 7
K42: Tier 2 | L42: Egypt | M42: =_xlfn.NORM.DIST(M8,M$29,M$30,TRUE) -> 0.084653343 | N42: =_xlfn.NORM.DIST(N8,N$29,N$30,TRUE) -> 0.17240986 | O42: =_xlfn.NORM.DIST(O8,O$29,O$30,TRUE) -> 0.35330545 | P42: =_xlfn.NORM.DIST(P8,P$29,P$30,TRUE) -> 0.0074158208 | Q42: =_xlfn.NORM.DIST(Q8,Q$29,Q$30,TRUE) -> 0.094452751 | R42: =_xlfn.NORM.DIST(R8,R$29,R$30,TRUE) -> 0.13395493 | S42: =_xlfn.NORM.DIST(S8,S$29,S$30,TRUE) -> 0.44053093 | T42: =_xlfn.NORM.DIST(T8,T$29,T$30,TRUE) -> 0.2699929 | ... V42: =_xlfn.NORM.DIST(V8,V$29,V$30,TRUE) -> 0.32022537 | AH42: 3.2
...

Sheet dataviz
C4: ='Country Decoder - Final 2503205'!K36 -> Tier | D4: ='Country Decoder - Final 2503205'!L36 -> Country | E4: ='Country Decoder - Final 2503205'!M36 -> Spends Per Trip Index | F4: ='Country Decoder - Final 2503205'!N36 -> Tourist Departures / Population Index | G4: ='Country Decoder - Final 2503205'!O36 -> Search Volume - 'Flight to Abu Dhabi' Index | H4: ='Country Decoder - Final 2503205'!P36 -> GDP - Growth Index | I4: ='Country Decoder - Final 2503205'!Q36 -> Disposable Personal Income (USD) Index | J4: ='Country Decoder - Final 2503205'!R36 -> Media Cost Index | ... N4: ='Country Decoder - Final 2503205'!V36 -> Audience Ratio vs. Total Population Index | O4: ='Country Decoder - Final 2503205'!X2 -> Weighted Score | P4: ='Country Decoder - Final 2503205'!Y2 -> % Split | Q4: ='Country Decoder - Final 2503205'!Z2 -> Budget Split | S4: Values for dropdowns:
C5: ='Country Decoder - Final 2503205'!K37 -> Tier 1 | D5: ='Country Decoder - Final 2503205'!L37 -> UAE | E5: ='Country Decoder - Final 2503205'!M37 -> 0.81422715 | F5: ='Country Decoder - Final 2503205'!N37 -> 0.9686742 | G5: ='Country Decoder - Final 2503205'!O37 -> 0.99999827 | H5: ='Country Decoder - Final 2503205'!P37 -> 0.50566487 | I5: ='Country Decoder - Final 2503205'!Q37 -> 0.78841486 | J5: ='Country Decoder - Final 2503205'!R37 -> 0.73004062 | ... N5: ='Country Decoder - Final 2503205'!V37 -> 0.83729573 | O5: ='Country Decoder - Final 2503205'!X3 -> 106.74562 | P5: ='Country Decoder - Final 2503205'!Y3 -> 0.034670708 | Q5: ='Country Decoder - Final 2503205'!Z3 -> 12134748 | S5: {=TRANSPOSE(D4:Q4)} -> Country
C6: ='Country Decoder - Final 2503205'!K38 -> Tier 1 | D6: ='Country Decoder - Final 2503205'!L38 -> USA | E6: ='Country Decoder - Final 2503205'!M38 -> 0.99799751 | F6: ='Country Decoder - Final 2503205'!N38 -> 0.24788984 | G6: ='Country Decoder - Final 2503205'!O38 -> 0.73717013 | H6: ='Country Decoder - Final 2503205'!P38 -> 0.69988112 | I6: ='Country Decoder - Final 2503205'!Q38 -> 0.99070243 | J6: ='Country Decoder - Final 2503205'!R38 -> 0.98552341 | ... N6: ='Country Decoder - Final 2503205'!V38 -> 0.2975989 | O6: ='Country Decoder - Final 2503205'!X4 -> 223.84196 | P6: ='Country Decoder - Final 2503205'!Y4 -> 0.072703305 | Q6: ='Country Decoder - Final 2503205'!Z4 -> 25446157 | S6: Spends Per Trip Index
C7: ='Country Decoder - Final 2503205'!K39 -> Tier 1 | D7: ='Country Decoder - Final 2503205'!L39 -> UK | E7: ='Country Decoder - Final 2503205'!M39 -> 0.83535601 | F7: ='Country Decoder - Final 2503205'!N39 -> 0.87519382 | G7: ='Country Decoder - Final 2503205'!O39 -> 0.62715562 | H7: ='Country Decoder - Final 2503205'!P39 -> 0.75761731 | I7: ='Country Decoder - Final 2503205'!Q39 -> 0.78944125 | J7: ='Country Decoder - Final 2503205'!R39 -> 0.89414785 | ... N7: ='Country Decoder - Final 2503205'!V39 -> 0.37317589 | O7: ='Country Decoder - Final 2503205'!X5 -> 220.45948 | P7: ='Country Decoder - Final 2503205'!Y5 -> 0.071604685 | Q7: ='Country Decoder - Final 2503205'!Z5 -> 25061640 | S7: Tourist Departures / Population Index
C8: ='Country Decoder - Final 2503205'!K40 -> Tier 1 | D8: ='Country Decoder - Final 2503205'!L40 -> Germany | E8: ='Country Decoder - Final 2503205'!M40 -> 0.59926381 | F8: ='Country Decoder - Final 2503205'!N40 -> 0.79737301 | G8: ='Country Decoder - Final 2503205'!O40 -> 0.51790353 | H8: ='Country Decoder - Final 2503205'!P40 -> 0.48025662 | I8: ='Country Decoder - Final 2503205'!Q40 -> 0.88481923 | J8: ='Country Decoder - Final 2503205'!R40 -> 0.69171174 | ... N8: ='Country Decoder - Final 2503205'!V40 -> 0.33705654 | O8: ='Country Decoder - Final 2503205'!X6 -> 211.90058 | P8: ='Country Decoder - Final 2503205'!Y6 -> 0.068824776 | Q8: ='Country Decoder - Final 2503205'!Z6 -> 24088672 | S8: Search Volume - 'Flight to Abu Dhabi' Index
C9: ='Country Decoder - Final 2503205'!K41 -> Tier 1 | D9: ='Country Decoder - Final 2503205'!L41 -> France | E9: ='Country Decoder - Final 2503205'!M41 -> 0.81174906 | F9: ='Country Decoder - Final 2503205'!N41 -> 0.44213243 | G9: ='Country Decoder - Final 2503205'!O41 -> 0.50093585 | H9: ='Country Decoder - Final 2503205'!P41 -> 0.45508321 | I9: ='Country Decoder - Final 2503205'!Q41 -> 0.76957735 | J9: ='Country Decoder - Final 2503205'!R41 -> 0.62311112 | ... N9: ='Country Decoder - Final 2503205'!V41 -> 0.34197668 | O9: ='Country Decoder - Final 2503205'!X7 -> 210.75121 | P9: ='Country Decoder - Final 2503205'!Y7 -> 0.068451464 | Q9: ='Country Decoder - Final 2503205'!Z7 -> 23958012 | S9: GDP - Growth Index
C10: ='Country Decoder - Final 2503205'!K42 -> Tier 2 | D10: ='Country Decoder - Final 2503205'!L42 -> Egypt | E10: ='Country Decoder - Final 2503205'!M42 -> 0.084653343 | F10: ='Country Decoder - Final 2503205'!N42 -> 0.17240986 | G10: ='Country Decoder - Final 2503205'!O42 -> 0.35330545 | H10: ='Country Decoder - Final 2503205'!P42 -> 0.0074158208 | I10: ='Country Decoder - Final 2503205'!Q42 -> 0.094452751 | J10: ='Country Decoder - Final 2503205'!R42 -> 0.13395493 | ... N10: ='Country Decoder - Final 2503205'!V42 -> 0.32022537 | O10: ='Country Decoder - Final 2503205'!X8 -> 59.364733 | P10: ='Country Decoder - Final 2503205'!Y8 -> 0.019281516 | Q10: ='Country Decoder - Final 2503205'!Z8 -> 6748530.5 | S10: Disposable Personal Income (USD) Index
C11: ='Country Decoder - Final 2503205'!K43 -> Tier 2 | D11: ='Country Decoder - Final 2503205'!L43 -> Khazakstan | E11: ='Country Decoder - Final 2503205'!M43 -> 0.18608978 | F11: ='Country Decoder - Final 2503205'!N43 -> 0.27146645 | G11: ='Country Decoder - Final 2503205'!O43 -> 0.33874554 | H11: ='Country Decoder - Final 2503205'!P43 -> 0.76888002 | I11: ='Country Decoder - Final 2503205'!Q43 -> 0.20013563 | J11: ='Country Decoder - Final 2503205'!R43 -> 0.10428167 | ... N11: ='Country Decoder - Final 2503205'!V43 -> 0.35493671 | O11: ='Country Decoder - Final 2503205'!X9 -> 66.696784 | P11: ='Country Decoder - Final 2503205'!Y9 -> 0.021662948 | Q11: ='Country Decoder - Final 2503205'!Z9 -> 7582031.7 | S11: Media Cost Index
C12: ='Country Decoder - Final 2503205'!K44 -> Tier 2 | D12: ='Country Decoder - Final 2503205'!L44 -> Bahrain | E12: ='Country Decoder - Final 2503205'!M44 -> 0.55223733 | F12: ='Country Decoder - Final 2503205'!N44 -> 0.81914765 | G12: ='Country Decoder - Final 2503205'!O44 -> 0.34427731 | H12: ='Country Decoder - Final 2503205'!P44 -> 0.48375383 | I12: ='Country Decoder - Final 2503205'!Q44 -> 0.56884944 | J12: ='Country Decoder - Final 2503205'!R44 -> 0.25495495 | ... N12: ='Country Decoder - Final 2503205'!V44 -> 0.99037523 | O12: ='Country Decoder - Final 2503205'!X10 -> 54.617531 | P12: ='Country Decoder - Final 2503205'!Y10 -> 0.017739637 | Q12: ='Country Decoder - Final 2503205'!Z10 -> 6208872.8 | S12: Global Explorers (Audience M) Index
C13: ='Country Decoder - Final 2503205'!K45 -> Tier 2 | D13: ='Country Decoder - Final 2503205'!L45 -> Qatar | E13: ='Country Decoder - Final 2503205'!M45 -> 0.53642212 | F13: ='Country Decoder - Final 2503205'!N45 -> 0.81725772 | G13: ='Country Decoder - Final 2503205'!O45 -> 0.34833716 | H13: ='Country Decoder - Final 2503205'!P45 -> 0.37600336 | I13: ='Country Decoder - Final 2503205'!Q45 -> 0.36118023 | J13: ='Country Decoder - Final 2503205'!R45 -> 0.40226976 | ... N13: ='Country Decoder - Final 2503205'!V45 -> 0.9993526 | O13: ='Country Decoder - Final 2503205'!X11 -> 65.091672 | P13: ='Country Decoder - Final 2503205'!Y11 -> 0.021141611 | Q13: ='Country Decoder - Final 2503205'!Z11 -> 7399563.9 | S13: Budget Split Index
C14: ='Country Decoder - Final 2503205'!K46 -> Tier 2 | D14: ='Country Decoder - Final 2503205'!L46 -> Canada | E14: ='Country Decoder - Final 2503205'!M46 -> 0.52428772 | F14: ='Country Decoder - Final 2503205'!N46 -> 0.59041571 | G14: ='Country Decoder - Final 2503205'!O46 -> 0.41025373 | H14: ='Country Decoder - Final 2503205'!P46 -> 0.27558156 | I14: ='Country Decoder - Final 2503205'!Q46 -> 0.78004355 | J14: ='Country Decoder - Final 2503205'!R46 -> 0.85584734 | ... N14: ='Country Decoder - Final 2503205'!V46 -> 0.30055854 | O14: ='Country Decoder - Final 2503205'!X12 -> 80.443355 | P14: ='Country Decoder - Final 2503205'!Y12 -> 0.026127799 | Q14: ='Country Decoder - Final 2503205'!Z12 -> 9144729.7 | S14: Market Tiering Index
C15: ='Country Decoder - Final 2503205'!K47 -> Tier 2 | D15: ='Country Decoder - Final 2503205'!L47 -> Romania | E15: ='Country Decoder - Final 2503205'!M47 -> 0.20988415 | F15: ='Country Decoder - Final 2503205'!N47 -> 0.79546914 | G15: ='Country Decoder - Final 2503205'!O47 -> 0.36559305 | H15: ='Country Decoder - Final 2503205'!P47 -> 0.43036255 | I15: ='Country Decoder - Final 2503205'!Q47 -> 0.16510313 | J15: ='Country Decoder - Final 2503205'!R47 -> 0.15970743 | ... N15: ='Country Decoder - Final 2503205'!V47 -> 0.35978484 | O15: ='Country Decoder - Final 2503205'!X13 -> 67.726059 | P15: ='Country Decoder - Final 2503205'!Y13 -> 0.021997253 | Q15: ='Country Decoder - Final 2503205'!Z13 -> 7699038.7 | S15: Audience Ratio vs. Total Population Index
C16: ='Country Decoder - Final 2503205'!K48 -> Tier 2 | D16: ='Country Decoder - Final 2503205'!L48 -> Oman | E16: ='Country Decoder - Final 2503205'!M48 -> 0.13262743 | F16: ='Country Decoder - Final 2503205'!N48 -> 0.89594508 | G16: ='Country Decoder - Final 2503205'!O48 -> 0.34648481 | H16: ='Country Decoder - Final 2503205'!P48 -> 0.16828105 | I16: ='Country Decoder - Final 2503205'!Q48 -> 0.34592061 | J16: ='Country Decoder - Final 2503205'!R48 -> 0.18850108 | ... N16: ='Country Decoder - Final 2503205'!V48 -> 0.38651521 | O16: ='Country Decoder - Final 2503205'!X14 -> 57.374399 | P16: ='Country Decoder - Final 2503205'!Y14 -> 0.01863506 | Q16: ='Country Decoder - Final 2503205'!Z14 -> 6522271.1 | S16: Weighted Score
C17: ='Country Decoder - Final 2503205'!K49 -> Tier 2 | D17: ='Country Decoder - Final 2503205'!L49 -> Spain | E17: ='Country Decoder - Final 2503205'!M49 -> 0.44343002 | F17: ='Country Decoder - Final 2503205'!N49 -> 0.24049568 | G17: ='Country Decoder - Final 2503205'!O49 -> 0.41429022 | H17: ='Country Decoder - Final 2503205'!P49 -> 0.69528076 | I17: ='Country Decoder - Final 2503205'!Q49 -> 0.69154698 | J17: ='Country Decoder - Final 2503205'!R49 -> 0.55037778 | ... N17: ='Country Decoder - Final 2503205'!V49 -> 0.29897301 | O17: ='Country Decoder - Final 2503205'!X15 -> 73.745254 | P17: ='Country Decoder - Final 2503205'!Y15 -> 0.023952273 | Q17: ='Country Decoder - Final 2503205'!Z15 -> 8383295.5 | S17: % Split
C18: ='Country Decoder - Final 2503205'!K50 -> Tier 2 | D18: ='Country Decoder - Final 2503205'!L50 -> Netherlands | E18: ='Country Decoder - Final 2503205'!M50 -> 0.78710832 | F18: ='Country Decoder - Final 2503205'!N50 -> 0.82838464 | G18: ='Country Decoder - Final 2503205'!O50 -> 0.38885122 | H18: ='Country Decoder - Final 2503205'!P50 -> 0.63278583 | I18: ='Country Decoder - Final 2503205'!Q50 -> 0.86298736 | J18: ='Country Decoder - Final 2503205'!R50 -> 0.65116975 | ... N18: ='Country Decoder - Final 2503205'!V50 -> 0.44920696 | O18: ='Country Decoder - Final 2503205'!X16 -> 78.538496 | P18: ='Country Decoder - Final 2503205'!Y16 -> 0.025509106 | Q18: ='Country Decoder - Final 2503205'!Z16 -> 8928187 | S18: Budget Split
C19: ='Country Decoder - Final 2503205'!K51 -> Tier 2 | D19: ='Country Decoder - Final 2503205'!L51 -> Japan | E19: ='Country Decoder - Final 2503205'!M51 -> 0.87257091 | F19: ='Country Decoder - Final 2503205'!N51 -> 0.08220548 | G19: ='Country Decoder - Final 2503205'!O51 -> 0.34612657 | H19: ='Country Decoder - Final 2503205'!P51 -> 0.65715307 | I19: ='Country Decoder - Final 2503205'!Q51 -> 0.61937017 | J19: ='Country Decoder - Final 2503205'!R51 -> 0.80915876 | ... N19: ='Country Decoder - Final 2503205'!V51 -> 0.25668985 | O19: ='Country Decoder - Final 2503205'!X17 -> 80.714099 | P19: ='Country Decoder - Final 2503205'!Y17 -> 0.026215736 | Q19: ='Country Decoder - Final 2503205'!Z17 -> 9175507.6
C20: ='Country Decoder - Final 2503205'!K52 -> Tier 2 | D20: ='Country Decoder - Final 2503205'!L52 -> Uzbekistan | E20: ='Country Decoder - Final 2503205'!M52 -> 0.49423737 | F20: ='Country Decoder - Final 2503205'!N52 -> 0.10484606 | G20: ='Country Decoder - Final 2503205'!O52 -> 0.33856504 | H20: ='Country Decoder - Final 2503205'!P52 -> 0.99752161 | I20: ='Country Decoder - Final 2503205'!Q52 -> 0.090672795 | J20: ='Country Decoder - Final 2503205'!R52 -> 0.069172666 | ... N20: ='Country Decoder - Final 2503205'!V52 -> 0.29871976 | O20: ='Country Decoder - Final 2503205'!X18 -> 65.584656 | P20: ='Country Decoder - Final 2503205'!Y18 -> 0.021301731 | Q20: ='Country Decoder - Final 2503205'!Z18 -> 7455605.9
C21: ='Country Decoder - Final 2503205'!K53 -> Tier 2 | D21: ='Country Decoder - Final 2503205'!L53 -> Poland | E21: ='Country Decoder - Final 2503205'!M53 -> 0.26235704 | F21: ='Country Decoder - Final 2503205'!N53 -> 0.84613678 | G21: ='Country Decoder - Final 2503205'!O53 -> 0.41402202 | H21: ='Country Decoder - Final 2503205'!P53 -> 0.88980672 | I21: ='Country Decoder - Final 2503205'!Q53 -> 0.20754378 | J21: ='Country Decoder - Final 2503205'!R53 -> 0.26711273 | ... N21: ='Country Decoder - Final 2503205'!V53 -> 0.4157675 | O21: ='Country Decoder - Final 2503205'!X19 -> 64.776156 | P21: ='Country Decoder - Final 2503205'!Y19 -> 0.021039132 | Q21: ='Country Decoder - Final 2503205'!Z19 -> 7363696.3
C22: ='Country Decoder - Final 2503205'!K54 -> Tier 2 | D22: ='Country Decoder - Final 2503205'!L54 -> South Korea | E22: ='Country Decoder - Final 2503205'!M54 -> 0.51642302 | F22: ='Country Decoder - Final 2503205'!N54 -> 0.29247389 | G22: ='Country Decoder - Final 2503205'!O54 -> 0.33774456 | H22: ='Country Decoder - Final 2503205'!P54 -> 0.089171252 | I22: ='Country Decoder - Final 2503205'!Q54 -> 0.79218182 | J22: ='Country Decoder - Final 2503205'!R54 -> 0.75419625 | ... N22: ='Country Decoder - Final 2503205'!V54 -> 0.25469926 | O22: ='Country Decoder - Final 2503205'!X20 -> 77.624376 | P22: ='Country Decoder - Final 2503205'!Y20 -> 0.025212202 | Q22: ='Country Decoder - Final 2503205'!Z20 -> 8824270.7
C23: ='Country Decoder - Final 2503205'!K55 -> Tier 2 | D23: ='Country Decoder - Final 2503205'!L55 -> Armenia | E23: ='Country Decoder - Final 2503205'!M55 -> 0.18255955 | F23: ='Country Decoder - Final 2503205'!N55 -> 0.38599079 | G23: ='Country Decoder - Final 2503205'!O55 -> 0.34433419 | H23: ='Country Decoder - Final 2503205'!P55 -> 0.56454111 | I23: ='Country Decoder - Final 2503205'!Q55 -> 0.099617206 | J23: ='Country Decoder - Final 2503205'!R55 -> 0.10428167 | ... N23: ='Country Decoder - Final 2503205'!V55 -> 0.43380111 | O23: ='Country Decoder - Final 2503205'!X21 -> 62.828597 | P23: ='Country Decoder - Final 2503205'!Y21 -> 0.02040657 | Q23: ='Country Decoder - Final 2503205'!Z21 -> 7142299.5
C24: ='Country Decoder - Final 2503205'!K56 -> Tier 2 | D24: ='Country Decoder - Final 2503205'!L56 -> Belgium | E24: ='Country Decoder - Final 2503205'!M56 -> 0.91951349 | F24: ='Country Decoder - Final 2503205'!N56 -> 0.80309592 | G24: ='Country Decoder - Final 2503205'!O56 -> 0.36407668 | H24: ='Country Decoder - Final 2503205'!P56 -> 0.64060253 | I24: ='Country Decoder - Final 2503205'!Q56 -> 0.81184582 | J24: ='Country Decoder - Final 2503205'!R56 -> 0.55037778 | ... N24: ='Country Decoder - Final 2503205'!V56 -> 0.39104041 | O24: ='Country Decoder - Final 2503205'!X22 -> 76.550766 | P24: ='Country Decoder - Final 2503205'!Y22 -> 0.024863496 | Q24: ='Country Decoder - Final 2503205'!Z22 -> 8702223.6
C25: ='Country Decoder - Final 2503205'!K57 -> Tier 1 | D25: ='Country Decoder - Final 2503205'!L57 -> Italy | E25: ='Country Decoder - Final 2503205'!M57 -> 0.69000436 | F25: ='Country Decoder - Final 2503205'!N57 -> 0.70529329 | G25: ='Country Decoder - Final 2503205'!O57 -> 0.4792406 | H25: ='Country Decoder - Final 2503205'!P57 -> 0.5025292 | I25: ='Country Decoder - Final 2503205'!Q57 -> 0.76389628 | J25: ='Country Decoder - Final 2503205'!R57 -> 0.69171174 | ... N25: ='Country Decoder - Final 2503205'!V57 -> 0.27758318 | O25: ='Country Decoder - Final 2503205'!X23 -> 210.60139 | P25: ='Country Decoder - Final 2503205'!Y23 -> 0.068402801 | Q25: ='Country Decoder - Final 2503205'!Z23 -> 23940980
C26: ='Country Decoder - Final 2503205'!K58 -> Tier 1 | D26: ='Country Decoder - Final 2503205'!L58 -> China | E26: ='Country Decoder - Final 2503205'!M58 -> 0.079733292 | F26: ='Country Decoder - Final 2503205'!N58 -> 0.065278592 | G26: ='Country Decoder - Final 2503205'!O58 -> 0.33451066 | H26: ='Country Decoder - Final 2503205'!P58 -> 0.54233301 | I26: ='Country Decoder - Final 2503205'!Q58 -> 0.13886032 | J26: ='Country Decoder - Final 2503205'!R58 -> 0.97709161 | ... N26: ='Country Decoder - Final 2503205'!V58 -> 0.29959349 | O26: ='Country Decoder - Final 2503205'!X24 -> 211.99148 | P26: ='Country Decoder - Final 2503205'!Y24 -> 0.068854299 | Q26: ='Country Decoder - Final 2503205'!Z24 -> 24099005
C27: ='Country Decoder - Final 2503205'!K59 -> Tier 1 | D27: ='Country Decoder - Final 2503205'!L59 -> Saudi Arabia | E27: ='Country Decoder - Final 2503205'!M59 -> 0.18744418 | F27: ='Country Decoder - Final 2503205'!N59 -> 0.42223463 | G27: ='Country Decoder - Final 2503205'!O59 -> 0.37443386 | H27: ='Country Decoder - Final 2503205'!P59 -> 0.31730084 | I27: ='Country Decoder - Final 2503205'!Q59 -> 0.21012055 | J27: ='Country Decoder - Final 2503205'!R59 -> 0.55037778 | ... N27: ='Country Decoder - Final 2503205'!V59 -> 0.61507582 | O27: ='Country Decoder - Final 2503205'!X25 -> 202.2057 | P27: ='Country Decoder - Final 2503205'!Y25 -> 0.065675902 | Q27: ='Country Decoder - Final 2503205'!Z25 -> 22986566
C28: ='Country Decoder - Final 2503205'!K60 -> Tier 1 | D28: ='Country Decoder - Final 2503205'!L60 -> Russia | E28: ='Country Decoder - Final 2503205'!M60 -> 0.17099309 | F28: ='Country Decoder - Final 2503205'!N60 -> 0.14348054 | G28: ='Country Decoder - Final 2503205'!O60 -> 0.49999989 | H28: ='Country Decoder - Final 2503205'!P60 -> 0.099706298 | I28: ='Country Decoder - Final 2503205'!Q60 -> 0.18971438 | J28: ='Country Decoder - Final 2503205'!R60 -> 0.18850108 | ... N28: ='Country Decoder - Final 2503205'!V60 -> 0.30138207 | O28: ='Country Decoder - Final 2503205'!X26 -> 193.9838 | P28: ='Country Decoder - Final 2503205'!Y26 -> 0.063005449 | Q28: ='Country Decoder - Final 2503205'!Z26 -> 22051907
C29: ='Country Decoder - Final 2503205'!K61 -> Tier 1 | D29: ='Country Decoder - Final 2503205'!L61 -> Kuwait | E29: ='Country Decoder - Final 2503205'!M61 -> 0.27317375 | F29: ='Country Decoder - Final 2503205'!N61 -> 0.3857894 | G29: ='Country Decoder - Final 2503205'!O61 -> 0.35165326 | H29: ='Country Decoder - Final 2503205'!P61 -> 0.11908674 | I29: ='Country Decoder - Final 2503205'!Q61 -> 0.5847747 | J29: ='Country Decoder - Final 2503205'!R61 -> 0.3595342 | ... N29: ='Country Decoder - Final 2503205'!V61 -> 0.97656992 | O29: ='Country Decoder - Final 2503205'!X27 -> 55.155708 | P29: ='Country Decoder - Final 2503205'!Y27 -> 0.017914435 | Q29: ='Country Decoder - Final 2503205'!Z27 -> 6270052.3
C30: ='Country Decoder - Final 2503205'!K62 -> Tier 1 | D30: ='Country Decoder - Final 2503205'!L62 -> India | E30: ='Country Decoder - Final 2503205'!M62 -> 0.37966311 | F30: ='Country Decoder - Final 2503205'!N62 -> 0.043909558 | G30: ='Country Decoder - Final 2503205'!O62 -> 0.78123905 | H30: ='Country Decoder - Final 2503205'!P62 -> 0.85869161 | I30: ='Country Decoder - Final 2503205'!Q62 -> 0.099355811 | J30: ='Country Decoder - Final 2503205'!R62 -> 0.15970743 | ... N30: ='Country Decoder - Final 2503205'!V62 -> 0.36651803 | O30: ='Country Decoder - Final 2503205'!X28 -> 199.52774 | P30: ='Country Decoder - Final 2503205'!Y28 -> 0.064806106 | Q30: ='Country Decoder - Final 2503205'!Z28 -> 22682137
D34: =_xlfn.CONCAT("Bubble Chart: ",D38," x ",E38," (Size: ",F38,")") -> Bubble Chart: Media Cost Index x Weighted Score (Size: Budget Split)
D36: Col A | E36: Col B | F36: Col C
D37: x-axis | E37: y-axis | F37: size
C38: Country | D38: Media Cost Index | E38: Weighted Score | F38: Budget Split
C39: =D5 -> UAE | D39: {=_xlfn._xlws.FILTER($D$5:$Q$30,$D$4:$Q$4=D38)} -> 0.73004062 | E39: {=_xlfn._xlws.FILTER($D$5:$Q$30,$D$4:$Q$4=E38)} -> 106.74562 | F39: {=_xlfn._xlws.FILTER($D$5:$Q$30,$D$4:$Q$4=F38)} -> 12134748
C40: =D6 -> USA | D40: 0.98552341 | E40: 223.84196 | F40: 25446157
C41: =D7 -> UK | D41: 0.89414785 | E41: 220.45948 | F41: 25061640
C42: =D8 -> Germany | D42: 0.69171174 | E42: 211.90058 | F42: 24088672
C43: =D9 -> France | D43: 0.62311112 | E43: 210.75121 | F43: 23958012
C44: =D10 -> Egypt | D44: 0.13395493 | E44: 59.364733 | F44: 6748530.5
C45: =D11 -> Khazakstan | D45: 0.10428167 | E45: 66.696784 | F45: 7582031.7
C46: =D12 -> Bahrain | D46: 0.25495495 | E46: 54.617531 | F46: 6208872.8
C47: =D13 -> Qatar | D47: 0.40226976 | E47: 65.091672 | F47: 7399563.9
...

Sheet Country Decoder - All Factors
V1: Outputs | W1: % | X1: 23760000
B2: Country | C2: =Trips!B1 -> Trips(000s) | D2: =Spend!B1 -> Spend(m-euro) | E2: ='Tourist Departures'!B1 -> Tourist Departures | F2: ='Minimum Wage'!B1 -> Hourly Minimum Wage | G2: =NoofMillionaires!B1 -> NoofMillionaires | H2: ='Inflation Rate'!B1 -> Inflation Rate | I2: =Population!B1 -> Population(m) | J2: ='Search Volume'!B2 -> SV -Abu Dhabi | K2: ='Search Volume'!C2 -> SV - Flights to Abu Dhabi | L2: ='Search Volume'!D2 -> 23SV -Abu Dhabi | M2: ='Search Volume'!E2 -> 23SV - Flights to Abu Dhabi | N2: ='Search Volume'!#REF! -> #REF! | O2: ='GDP Per Capita'!B1 -> GDP Per Capita | P2: =StandardofLiving!B1 -> HDI | Q2: =MAS!B1 -> Median Annual Salary (USD) | R2: =GDP!C1 -> GDP - 2025 | S2: =GDP!D1 -> GDP - Growth | T2: =DPI!B1 -> Disposable Personal Income (USD) | U2: ='Cost of Media'!B1 -> Media Cost | V2: Weighted Score | X2: Budget Split
B3: UAE | C3: =VLOOKUP(B3,Trips!$A$1:$B$27,2,FALSE) -> 0 | D3: =VLOOKUP(B3,Spend!$A$1:$B$27,2,FALSE) -> #N/A | E3: =VLOOKUP(B3,'Tourist Departures'!$A$1:$B$27,2,FALSE) -> 18906000 | F3: =VLOOKUP(B3,'Minimum Wage'!$A$1:$B$27,2,FALSE) -> 6 | G3: =VLOOKUP(B3,NoofMillionaires!$A$1:$B$27,2,FALSE) -> 116500 | H3: =VLOOKUP(B3,'Inflation Rate'!$A$1:$B$27,2,FALSE) -> 0.026 | I3: =VLOOKUP(B3,Population!$A$1:$B$27,2,FALSE) -> 11350000 | J3: =VLOOKUP(B3,'Search Volume'!$A$2:$C$28,2,FALSE) -> 18791890 | K3: =VLOOKUP(B3,'Search Volume'!$A$2:$C$28,3,FALSE) -> 69430 | L3: =VLOOKUP(B3,'Search Volume'!$A$2:$E$28,4,FALSE) -> 9975490 | M3: =VLOOKUP(B3,'Search Volume'!$A$2:$E$28,5,FALSE) -> 85740 | N3: =VLOOKUP(B3,'Search Volume'!$A$2:$C$14,6,FALSE) -> #REF! | O3: =VLOOKUP(B3,'GDP Per Capita'!$A$1:$B$27,2,FALSE) -> 49377.564 | P3: =VLOOKUP(B3,StandardofLiving!$A$1:$B$27,2,FALSE) -> 0.94 | Q3: =VLOOKUP(B3,MAS!$A$1:$B$27,2,FALSE) -> 22037 | R3: =VLOOKUP(B3,GDP!$A$2:$D$28,3,FALSE) -> 548.598 | S3: =VLOOKUP(B3,GDP!$A$2:$D$28,4,FALSE) -> 0.021447497 | T3: =VLOOKUP(B3,DPI!$A$1:$B$27,2,FALSE) -> 36020 | U3: =VLOOKUP(B3,'Cost of Media'!$A$1:$B$27,2,FALSE) -> #N/A | V3: 17.325899 | W3: =V3/SUM($V$4:$V$27) -> 0.054768484 | X3: =W3*$X$1 -> 1301299.2
B4: USA | C4: =VLOOKUP(B4,Trips!$A$1:$B$27,2,FALSE) -> 704.9 | D4: =VLOOKUP(B4,Spend!$A$1:$B$27,2,FALSE) -> #N/A | E4: =VLOOKUP(B4,'Tourist Departures'!$A$1:$B$27,2,FALSE) -> 1.7093009e+08 | F4: =VLOOKUP(B4,'Minimum Wage'!$A$1:$B$27,2,FALSE) -> 7.25 | G4: =VLOOKUP(B4,NoofMillionaires!$A$1:$B$27,2,FALSE) -> 24480000 | H4: =VLOOKUP(B4,'Inflation Rate'!$A$1:$B$27,2,FALSE) -> 0.031 | I4: =VLOOKUP(B4,Population!$A$1:$B$27,2,FALSE) -> 347402264 | J4: =VLOOKUP(B4,'Search Volume'!$A$2:$C$28,2,FALSE) -> 3036780 | K4: =VLOOKUP(B4,'Search Volume'!$A$2:$C$28,3,FALSE) -> 70340 | L4: =VLOOKUP(B4,'Search Volume'!$A$2:$E$28,4,FALSE) -> 2947460 | M4: =VLOOKUP(B4,'Search Volume'!$A$2:$E$28,5,FALSE) -> 48810 | N4: =VLOOKUP(B4,'Search Volume'!$A$2:$C$14,6,FALSE) -> #REF! | O4: =VLOOKUP(B4,'GDP Per Capita'!$A$1:$B$27,2,FALSE) -> 85809.9 | P4: =VLOOKUP(B4,StandardofLiving!$A$1:$B$27,2,FALSE) -> 0.938 | Q4: =VLOOKUP(B4,MAS!$A$1:$B$27,2,FALSE) -> 67468 | R4: =VLOOKUP(B4,GDP!$A$2:$D$28,3,FALSE) -> 30507 | S4: =VLOOKUP(B4,GDP!$A$2:$D$28,4,FALSE) -> 0.045333059 | T4: =VLOOKUP(B4,DPI!$A$1:$B$27,2,FALSE) -> 60944 | U4: =VLOOKUP(B4,'Cost of Media'!$A$1:$B$27,2,FALSE) -> #N/A | V4: 18.325899 | W4: =V4/SUM($V$4:$V$27) -> 0.05792956 | X4: =W4*$X$1 -> 1376406.3
A5: Great Britain | B5: UK | C5: =VLOOKUP(B5,Trips!$A$1:$B$27,2,FALSE) -> 1245.1 | D5: =VLOOKUP(B5,Spend!$A$1:$B$27,2,FALSE) -> #N/A | E5: =VLOOKUP(B5,'Tourist Departures'!$A$1:$B$27,2,FALSE) -> 93086000 | F5: =VLOOKUP(B5,'Minimum Wage'!$A$1:$B$27,2,FALSE) -> 14.3 | G5: =VLOOKUP(B5,NoofMillionaires!$A$1:$B$27,2,FALSE) -> 2849000 | H5: =VLOOKUP(B5,'Inflation Rate'!$A$1:$B$27,2,FALSE) -> 0.029 | I5: =VLOOKUP(B5,Population!$A$1:$B$27,2,FALSE) -> 69579448 | J5: =VLOOKUP(B5,'Search Volume'!$A$2:$C$28,2,FALSE) -> 2248410 | K5: =VLOOKUP(B5,'Search Volume'!$A$2:$C$28,3,FALSE) -> 169080 | L5: =VLOOKUP(B5,'Search Volume'!$A$2:$E$28,4,FALSE) -> 1782130 | M5: =VLOOKUP(B5,'Search Volume'!$A$2:$E$28,5,FALSE) -> 136400 | N5: =VLOOKUP(B5,'Search Volume'!$A$2:$C$14,6,FALSE) -> #REF! | O5: =VLOOKUP(B5,'GDP Per Capita'!$A$1:$B$27,2,FALSE) -> 52636.787 | P5: =VLOOKUP(B5,StandardofLiving!$A$1:$B$27,2,FALSE) -> 0.946 | Q5: =VLOOKUP(B5,MAS!$A$1:$B$27,2,FALSE) -> 45486 | R5: =VLOOKUP(B5,GDP!$A$2:$D$28,3,FALSE) -> 3839 | S5: =VLOOKUP(B5,GDP!$A$2:$D$28,4,FALSE) -> 0.053512623 | T5: =VLOOKUP(B5,DPI!$A$1:$B$27,2,FALSE) -> 36077 | U5: =VLOOKUP(B5,'Cost of Media'!$A$1:$B$27,2,FALSE) -> #N/A | V5: 16.61223 | W5: =V5/SUM($V$4:$V$27) -> 0.052512523 | X5: =W5*$X$1 -> 1247697.6
B6: Germany | C6: =VLOOKUP(B6,Trips!$A$1:$B$27,2,FALSE) -> 504.2 | D6: =VLOOKUP(B6,Spend!$A$1:$B$27,2,FALSE) -> 430 | E6: =VLOOKUP(B6,'Tourist Departures'!$A$1:$B$27,2,FALSE) -> 99533000 | F6: =VLOOKUP(B6,'Minimum Wage'!$A$1:$B$27,2,FALSE) -> 13.85 | G6: =VLOOKUP(B6,NoofMillionaires!$A$1:$B$27,2,FALSE) -> 2683000 | H6: =VLOOKUP(B6,'Inflation Rate'!$A$1:$B$27,2,FALSE) -> 0.026 | I6: =VLOOKUP(B6,Population!$A$1:$B$27,2,FALSE) -> 83600000 | J6: =VLOOKUP(B6,'Search Volume'!$A$2:$C$28,2,FALSE) -> 1384090 | K6: =VLOOKUP(B6,'Search Volume'!$A$2:$C$28,3,FALSE) -> 5530 | L6: =VLOOKUP(B6,'Search Volume'!$A$2:$E$28,4,FALSE) -> 1351080 | M6: =VLOOKUP(B6,'Search Volume'!$A$2:$E$28,5,FALSE) -> 3820 | N6: =VLOOKUP(B6,'Search Volume'!$A$2:$C$14,6,FALSE) -> #REF! | O6: =VLOOKUP(B6,'GDP Per Capita'!$A$1:$B$27,2,FALSE) -> 55800.219 | P6: =VLOOKUP(B6,StandardofLiving!$A$1:$B$27,2,FALSE) -> 0.959 | Q6: =VLOOKUP(B6,MAS!$A$1:$B$27,2,FALSE) -> 55055 | R6: =VLOOKUP(B6,GDP!$A$2:$D$28,3,FALSE) -> 4744 | S6: =VLOOKUP(B6,GDP!$A$2:$D$28,4,FALSE) -> 0.01846286 | T6: =VLOOKUP(B6,DPI!$A$1:$B$27,2,FALSE) -> 42417 | U6: =VLOOKUP(B6,'Cost of Media'!$A$1:$B$27,2,FALSE) -> #N/A | V6: 12.163844 | W6: =V6/SUM($V$4:$V$27) -> 0.038450836 | X6: =W6*$X$1 -> 913591.87
B7: France | C7: =VLOOKUP(B7,Trips!$A$1:$B$27,2,FALSE) -> 433.9 | D7: =VLOOKUP(B7,Spend!$A$1:$B$27,2,FALSE) -> 362 | E7: =VLOOKUP(B7,'Tourist Departures'!$A$1:$B$27,2,FALSE) -> 49276000 | F7: =VLOOKUP(B7,'Minimum Wage'!$A$1:$B$27,2,FALSE) -> 12.96 | G7: =VLOOKUP(B7,NoofMillionaires!$A$1:$B$27,2,FALSE) -> 2796000 | H7: =VLOOKUP(B7,'Inflation Rate'!$A$1:$B$27,2,FALSE) -> 0.028 | I7: =VLOOKUP(B7,Population!$A$1:$B$27,2,FALSE) -> 66658005 | J7: =VLOOKUP(B7,'Search Volume'!$A$2:$C$28,2,FALSE) -> 1319680 | K7: =VLOOKUP(B7,'Search Volume'!$A$2:$C$28,3,FALSE) -> 4240 | L7: =VLOOKUP(B7,'Search Volume'!$A$2:$E$28,4,FALSE) -> 1175450 | M7: =VLOOKUP(B7,'Search Volume'!$A$2:$E$28,5,FALSE) -> 2830 | N7: =VLOOKUP(B7,'Search Volume'!$A$2:$C$14,6,FALSE) -> #REF! | O7: =VLOOKUP(B7,'GDP Per Capita'!$A$1:$B$27,2,FALSE) -> 46150.488 | P7: =VLOOKUP(B7,StandardofLiving!$A$1:$B$27,2,FALSE) -> 0.92 | Q7: =VLOOKUP(B7,MAS!$A$1:$B$27,2,FALSE) -> 48072 | R7: =VLOOKUP(B7,GDP!$A$2:$D$28,3,FALSE) -> 3211 | S7: =VLOOKUP(B7,GDP!$A$2:$D$28,4,FALSE) -> 0.015496521 | T7: =VLOOKUP(B7,DPI!$A$1:$B$27,2,FALSE) -> 35001 | U7: =VLOOKUP(B7,'Cost of Media'!$A$1:$B$27,2,FALSE) -> 0.042772724 | V7: 8.9095183 | W7: =V7/SUM($V$4:$V$27) -> 0.028163665 | X7: =W7*$X$1 -> 669168.69
B8: Egypt | C8: =VLOOKUP(B8,Trips!$A$1:$B$27,2,FALSE) -> 170 | D8: =VLOOKUP(B8,Spend!$A$1:$B$27,2,FALSE) -> #N/A | E8: =VLOOKUP(B8,'Tourist Departures'!$A$1:$B$27,2,FALSE) -> 43066000 | F8: =VLOOKUP(B8,'Minimum Wage'!$A$1:$B$27,2,FALSE) -> 0.73 | G8: =VLOOKUP(B8,NoofMillionaires!$A$1:$B$27,2,FALSE) -> 87000 | H8: =VLOOKUP(B8,'Inflation Rate'!$A$1:$B$27,2,FALSE) -> 0.282 | I8: =VLOOKUP(B8,Population!$A$1:$B$27,2,FALSE) -> 116275465 | J8: =VLOOKUP(B8,'Search Volume'!$A$2:$C$28,2,FALSE) -> 172870 | K8: =VLOOKUP(B8,'Search Volume'!$A$2:$C$28,3,FALSE) -> 14650 | L8: =VLOOKUP(B8,'Search Volume'!$A$2:$E$28,4,FALSE) -> 149110 | M8: =VLOOKUP(B8,'Search Volume'!$A$2:$E$28,5,FALSE) -> 8400 | N8: =VLOOKUP(B8,'Search Volume'!$A$2:$C$14,6,FALSE) -> #REF! | O8: =VLOOKUP(B8,'GDP Per Capita'!$A$1:$B$27,2,FALSE) -> 3338.4737 | P8: =VLOOKUP(B8,StandardofLiving!$A$1:$B$27,2,FALSE) -> 0.754 | Q8: =VLOOKUP(B8,MAS!$A$1:$B$27,2,FALSE) -> 12500 | R8: =VLOOKUP(B8,GDP!$A$2:$D$28,3,FALSE) -> 347.342 | S8: =VLOOKUP(B8,GDP!$A$2:$D$28,4,FALSE) -> -0.093359853 | T8: =VLOOKUP(B8,DPI!$A$1:$B$27,2,FALSE) -> 2072 | U8: =VLOOKUP(B8,'Cost of Media'!$A$1:$B$27,2,FALSE) -> #N/A | V8: 7.4276786 | W8: =V8/SUM($V$4:$V$27) -> 0.023479457 | X8: =W8*$X$1 -> 557871.9
B9: Khazakstan | C9: =VLOOKUP(B9,Trips!$A$1:$B$27,2,FALSE) -> 74 | D9: =VLOOKUP(B9,Spend!$A$1:$B$27,2,FALSE) -> #N/A | E9: =VLOOKUP(B9,'Tourist Departures'!$A$1:$B$27,2,FALSE) -> 10707000 | F9: =VLOOKUP(B9,'Minimum Wage'!$A$1:$B$27,2,FALSE) -> 1.09 | G9: =VLOOKUP(B9,NoofMillionaires!$A$1:$B$27,2,FALSE) -> 44307 | H9: =VLOOKUP(B9,'Inflation Rate'!$A$1:$B$27,2,FALSE) -> 0.087 | I9: =VLOOKUP(B9,Population!$A$1:$B$27,2,FALSE) -> 20370672 | J9: =VLOOKUP(B9,'Search Volume'!$A$2:$C$28,2,FALSE) -> 71900 | K9: =VLOOKUP(B9,'Search Volume'!$A$2:$C$28,3,FALSE) -> 290 | L9: =VLOOKUP(B9,'Search Volume'!$A$2:$E$28,4,FALSE) -> 47810 | M9: =VLOOKUP(B9,'Search Volume'!$A$2:$E$28,5,FALSE) -> 190 | N9: =VLOOKUP(B9,'Search Volume'!$A$2:$C$14,6,FALSE) -> #N/A | O9: =VLOOKUP(B9,'GDP Per Capita'!$A$1:$B$27,2,FALSE) -> 3161.7001 | P9: =VLOOKUP(B9,StandardofLiving!$A$1:$B$27,2,FALSE) -> 0.74 | Q9: =VLOOKUP(B9,MAS!$A$1:$B$27,2,FALSE) -> 13348 | R9: =VLOOKUP(B9,GDP!$A$2:$D$28,3,FALSE) -> 300.538 | S9: =VLOOKUP(B9,GDP!$A$2:$D$28,4,FALSE) -> 0.05522278 | T9: =VLOOKUP(B9,DPI!$A$1:$B$27,2,FALSE) -> 9660 | U9: =VLOOKUP(B9,'Cost of Media'!$A$1:$B$27,2,FALSE) -> 0 | V9: 6.8810569 | W9: =V9/SUM($V$4:$V$27) -> 0.021751544 | X9: =W9*$X$1 -> 516816.69
B10: Bahrain | C10: =VLOOKUP(B10,Trips!$A$1:$B$27,2,FALSE) -> 52.4 | D10: =VLOOKUP(B10,Spend!$A$1:$B$27,2,FALSE) -> #N/A | E10: =VLOOKUP(B10,'Tourist Departures'!$A$1:$B$27,2,FALSE) -> 2950000 | F10: =VLOOKUP(B10,'Minimum Wage'!$A$1:$B$27,2,FALSE) -> 7 | G10: =VLOOKUP(B10,NoofMillionaires!$A$1:$B$27,2,FALSE) -> 25000 | H10: =VLOOKUP(B10,'Inflation Rate'!$A$1:$B$27,2,FALSE) -> 0.021 | I10: =VLOOKUP(B10,Population!$A$1:$B$27,2,FALSE) -> 1588670 | J10: =VLOOKUP(B10,'Search Volume'!$A$2:$C$28,2,FALSE) -> 94410 | K10: =VLOOKUP(B10,'Search Volume'!$A$2:$C$28,3,FALSE) -> 12270 | L10: =VLOOKUP(B10,'Search Volume'!$A$2:$E$28,4,FALSE) -> 87090 | M10: =VLOOKUP(B10,'Search Volume'!$A$2:$E$28,5,FALSE) -> 12260 | N10: =VLOOKUP(B10,'Search Volume'!$A$2:$C$14,6,FALSE) -> #N/A | O10: =VLOOKUP(B10,'GDP Per Capita'!$A$1:$B$27,2,FALSE) -> 30048.218 | P10: =VLOOKUP(B10,StandardofLiving!$A$1:$B$27,2,FALSE) -> 0.899 | Q10: =VLOOKUP(B10,MAS!$A$1:$B$27,2,FALSE) -> 56393 | R10: =VLOOKUP(B10,GDP!$A$2:$D$28,3,FALSE) -> 47.829 | S10: =VLOOKUP(B10,GDP!$A$2:$D$28,4,FALSE) -> 0.018873954 | T10: =VLOOKUP(B10,DPI!$A$1:$B$27,2,FALSE) -> 25947 | U10: =VLOOKUP(B10,'Cost of Media'!$A$1:$B$27,2,FALSE) -> 0 | V10: 9.2950082 | W10: =V10/SUM($V$4:$V$27) -> 0.029382228 | X10: =W10*$X$1 -> 698121.74
B11: Qatar | C11: =VLOOKUP(B11,Trips!$A$1:$B$27,2,FALSE) -> 0 | D11: =VLOOKUP(B11,Spend!$A$1:$B$27,2,FALSE) -> #N/A | E11: =VLOOKUP(B11,'Tourist Departures'!$A$1:$B$27,2,FALSE) -> 3550000 | F11: =VLOOKUP(B11,'Minimum Wage'!$A$1:$B$27,2,FALSE) -> 1.59 | G11: =VLOOKUP(B11,NoofMillionaires!$A$1:$B$27,2,FALSE) -> 36000 | H11: =VLOOKUP(B11,'Inflation Rate'!$A$1:$B$27,2,FALSE) -> 0.024 | I11: =VLOOKUP(B11,Population!$A$1:$B$27,2,FALSE) -> 2757220 | J11: =VLOOKUP(B11,'Search Volume'!$A$2:$C$28,2,FALSE) -> 139980 | K11: =VLOOKUP(B11,'Search Volume'!$A$2:$C$28,3,FALSE) -> 16220 | L11: =VLOOKUP(B11,'Search Volume'!$A$2:$E$28,4,FALSE) -> 98020 | M11: =VLOOKUP(B11,'Search Volume'!$A$2:$E$28,5,FALSE) -> 14480 | N11: =VLOOKUP(B11,'Search Volume'!$A$2:$C$14,6,FALSE) -> #N/A | O11: =VLOOKUP(B11,'GDP Per Capita'!$A$1:$B$27,2,FALSE) -> 76275.908 | P11: =VLOOKUP(B11,StandardofLiving!$A$1:$B$27,2,FALSE) -> 0.886 | Q11: =VLOOKUP(B11,MAS!$A$1:$B$27,2,FALSE) -> 45560 | R11: =VLOOKUP(B11,GDP!$A$2:$D$28,3,FALSE) -> 222.776 | S11: =VLOOKUP(B11,GDP!$A$2:$D$28,4,FALSE) -> 0.0059787223 | T11: =VLOOKUP(B11,DPI!$A$1:$B$27,2,FALSE) -> 17459 | U11: =VLOOKUP(B11,'Cost of Media'!$A$1:$B$27,2,FALSE) -> #N/A | V11: 10.295008 | W11: =V11/SUM($V$4:$V$27) -> 0.032543304 | X11: =W11*$X$1 -> 773228.91
B12: Canada | C12: =VLOOKUP(B12,Trips!$A$1:$B$27,2,FALSE) -> 59 | D12: =VLOOKUP(B12,Spend!$A$1:$B$27,2,FALSE) -> 255 | E12: =VLOOKUP(B12,'Tourist Departures'!$A$1:$B$27,2,FALSE) -> 37845898 | F12: =VLOOKUP(B12,'Minimum Wage'!$A$1:$B$27,2,FALSE) -> 12.63 | G12: =VLOOKUP(B12,NoofMillionaires!$A$1:$B$27,2,FALSE) -> 2291000 | H12: =VLOOKUP(B12,'Inflation Rate'!$A$1:$B$27,2,FALSE) -> 0.029 | I12: =VLOOKUP(B12,Population!$A$1:$B$27,2,FALSE) -> 41500000 | J12: =VLOOKUP(B12,'Search Volume'!$A$2:$C$28,2,FALSE) -> 604940 | K12: =VLOOKUP(B12,'Search Volume'!$A$2:$C$28,3,FALSE) -> 9120 | L12: =VLOOKUP(B12,'Search Volume'!$A$2:$E$28,4,FALSE) -> 575590 | M12: =VLOOKUP(B12,'Search Volume'!$A$2:$E$28,5,FALSE) -> 6950 | N12: =VLOOKUP(B12,'Search Volume'!$A$2:$C$14,6,FALSE) -> #N/A | O12: =VLOOKUP(B12,'GDP Per Capita'!$A$1:$B$27,2,FALSE) -> 54282.618 | P12: =VLOOKUP(B12,StandardofLiving!$A$1:$B$27,2,FALSE) -> 0.939 | Q12: =VLOOKUP(B12,MAS!$A$1:$B$27,2,FALSE) -> 45345 | R12: =VLOOKUP(B12,GDP!$A$2:$D$28,3,FALSE) -> 2225 | S12: =VLOOKUP(B12,GDP!$A$2:$D$28,4,FALSE) -> -0.0071396698 | T12: =VLOOKUP(B12,DPI!$A$1:$B$27,2,FALSE) -> 35561 | U12: =VLOOKUP(B12,'Cost of Media'!$A$1:$B$27,2,FALSE) -> 0.031657955 | V12: 11.295008 | W12: =V12/SUM($V$4:$V$27) -> 0.03570438 | X12: =W12*$X$1 -> 848336.07
B13: Romania | C13: =VLOOKUP(B13,Trips!$A$1:$B$27,2,FALSE) -> 35.1 | D13: =VLOOKUP(B13,Spend!$A$1:$B$27,2,FALSE) -> #N/A | E13: =VLOOKUP(B13,'Tourist Departures'!$A$1:$B$27,2,FALSE) -> 23066000 | F13: =VLOOKUP(B13,'Minimum Wage'!$A$1:$B$27,2,FALSE) -> 4.14 | G13: =VLOOKUP(B13,NoofMillionaires!$A$1:$B$27,2,FALSE) -> 37000 | H13: =VLOOKUP(B13,'Inflation Rate'!$A$1:$B$27,2,FALSE) -> 0.072 | I13: =VLOOKUP(B13,Population!$A$1:$B$27,2,FALSE) -> 19424322 | J13: =VLOOKUP(B13,'Search Volume'!$A$2:$C$28,2,FALSE) -> 286520 | K13: =VLOOKUP(B13,'Search Volume'!$A$2:$C$28,3,FALSE) -> 760 | L13: =VLOOKUP(B13,'Search Volume'!$A$2:$E$28,4,FALSE) -> 244350 | M13: =VLOOKUP(B13,'Search Volume'!$A$2:$E$28,5,FALSE) -> 570 | N13: =VLOOKUP(B13,'Search Volume'!$A$2:$C$14,6,FALSE) -> #N/A | O13: =VLOOKUP(B13,'GDP Per Capita'!$A$1:$B$27,2,FALSE) -> 20072.408 | P13: =VLOOKUP(B13,StandardofLiving!$A$1:$B$27,2,FALSE) -> 0.845 | Q13: =VLOOKUP(B13,MAS!$A$1:$B$27,2,FALSE) -> 16660 | R13: =VLOOKUP(B13,GDP!$A$2:$D$28,3,FALSE) -> 403 | S13: =VLOOKUP(B13,GDP!$A$2:$D$28,4,FALSE) -> 0.012562814 | T13: =VLOOKUP(B13,DPI!$A$1:$B$27,2,FALSE) -> 7532 | U13: =VLOOKUP(B13,'Cost of Media'!$A$1:$B$27,2,FALSE) -> 0 | V13: 12.295008 | W13: =V13/SUM($V$4:$V$27) -> 0.038865456 | X13: =W13*$X$1 -> 923443.24
B14: Oman | C14: =VLOOKUP(B14,Trips!$A$1:$B$27,2,FALSE) -> 1565.8 | D14: =VLOOKUP(B14,Spend!$A$1:$B$27,2,FALSE) -> #N/A | E14: =VLOOKUP(B14,'Tourist Departures'!$A$1:$B$27,2,FALSE) -> 6633000 | F14: =VLOOKUP(B14,'Minimum Wage'!$A$1:$B$27,2,FALSE) -> 4.88 | G14: =VLOOKUP(B14,NoofMillionaires!$A$1:$B$27,2,FALSE) -> 30000 | H14: =VLOOKUP(B14,'Inflation Rate'!$A$1:$B$27,2,FALSE) -> 0.018 | I14: =VLOOKUP(B14,Population!$A$1:$B$27,2,FALSE) -> 4780706 | J14: =VLOOKUP(B14,'Search Volume'!$A$2:$C$28,2,FALSE) -> 139390 | K14: =VLOOKUP(B14,'Search Volume'!$A$2:$C$28,3,FALSE) -> 1260 | L14: =VLOOKUP(B14,'Search Volume'!$A$2:$E$28,4,FALSE) -> 98490 | M14: =VLOOKUP(B14,'Search Volume'!$A$2:$E$28,5,FALSE) -> 1000 | N14: =VLOOKUP(B14,'Search Volume'!$A$2:$C$14,6,FALSE) -> #N/A | O14: =VLOOKUP(B14,'GDP Per Capita'!$A$1:$B$27,2,FALSE) -> 20248.417 | P14: =VLOOKUP(B14,StandardofLiving!$A$1:$B$27,2,FALSE) -> 0.858 | Q14: =VLOOKUP(B14,MAS!$A$1:$B$27,2,FALSE) -> 20470 | R14: =VLOOKUP(B14,GDP!$A$2:$D$28,3,FALSE) -> 104.351 | S14: =VLOOKUP(B14,GDP!$A$2:$D$28,4,FALSE) -> -0.02423721 | T14: =VLOOKUP(B14,DPI!$A$1:$B$27,2,FALSE) -> 16800 | U14: =VLOOKUP(B14,'Cost of Media'!$A$1:$B$27,2,FALSE) -> #N/A | V14: 13.295008 | W14: =V14/SUM($V$4:$V$27) -> 0.042026532 | X14: =W14*$X$1 -> 998550.41
B15: Spain | C15: =VLOOKUP(B15,Trips!$A$1:$B$27,2,FALSE) -> 52.8 | D15: =VLOOKUP(B15,Spend!$A$1:$B$27,2,FALSE) -> 264 | E15: =VLOOKUP(B15,'Tourist Departures'!$A$1:$B$27,2,FALSE) -> 22816000 | F15: =VLOOKUP(B15,'Minimum Wage'!$A$1:$B$27,2,FALSE) -> 8.24 | G15: =VLOOKUP(B15,NoofMillionaires!$A$1:$B$27,2,FALSE) -> 1132000 | H15: =VLOOKUP(B15,'Inflation Rate'!$A$1:$B$27,2,FALSE) -> 0.034 | I15: =VLOOKUP(B15,Population!$A$1:$B$27,2,FALSE) -> 47420024 | J15: =VLOOKUP(B15,'Search Volume'!$A$2:$C$28,2,FALSE) -> 641800 | K15: =VLOOKUP(B15,'Search Volume'!$A$2:$C$28,3,FALSE) -> 2170 | L15: =VLOOKUP(B15,'Search Volume'!$A$2:$E$28,4,FALSE) -> 609940 | M15: =VLOOKUP(B15,'Search Volume'!$A$2:$E$28,5,FALSE) -> 1750 | N15: =VLOOKUP(B15,'Search Volume'!$A$2:$C$14,6,FALSE) -> #N/A | O15: =VLOOKUP(B15,'GDP Per Capita'!$A$1:$B$27,2,FALSE) -> 35297.009 | P15: =VLOOKUP(B15,StandardofLiving!$A$1:$B$27,2,FALSE) -> 0.918 | Q15: =VLOOKUP(B15,MAS!$A$1:$B$27,2,FALSE) -> 39965 | R15: =VLOOKUP(B15,GDP!$A$2:$D$28,3,FALSE) -> 1799 | S15: =VLOOKUP(B15,GDP!$A$2:$D$28,4,FALSE) -> 0.044715447 | T15: =VLOOKUP(B15,DPI!$A$1:$B$27,2,FALSE) -> 31193 | U15: =VLOOKUP(B15,'Cost of Media'!$A$1:$B$27,2,FALSE) -> 0.096328877 | V15: 14.295008 | W15: =V15/SUM($V$4:$V$27) -> 0.045187608 | X15: =W15*$X$1 -> 1073657.6
